2019-10-06 20:44:58,169 INFO: Microblog startup [ in e:\Users\Caio\Documents\Python\Microblog\app\__init__.py:43]
2019-10-06 20:45:35,211 ERROR: Exception on /edit_profile [POST] [ in e:\Users\Caio\Documents\Python\Microblog\venv\lib\site-packages\flask\app.py:1891]
Traceback (most recent call last):
  File "e:\Users\Caio\Documents\Python\Microblog\venv\lib\site-packages\sqlalchemy\engine\base.py", line 1244, in _execute_context
    cursor, statement, parameters, context
  File "e:\Users\Caio\Documents\Python\Microblog\venv\lib\site-packages\sqlalchemy\engine\default.py", line 552, in do_execute
    cursor.execute(statement, parameters)
sqlite3.IntegrityError: UNIQUE constraint failed: user.username

The above exception was the direct cause of the following exception:

Traceback (most recent call last):
  File "e:\Users\Caio\Documents\Python\Microblog\venv\lib\site-packages\flask\app.py", line 2446, in wsgi_app
    response = self.full_dispatch_request()
  File "e:\Users\Caio\Documents\Python\Microblog\venv\lib\site-packages\flask\app.py", line 1951, in full_dispatch_request
    rv = self.handle_user_exception(e)
  File "e:\Users\Caio\Documents\Python\Microblog\venv\lib\site-packages\flask\app.py", line 1820, in handle_user_exception
    reraise(exc_type, exc_value, tb)
  File "e:\Users\Caio\Documents\Python\Microblog\venv\lib\site-packages\flask\_compat.py", line 39, in reraise
    raise value
  File "e:\Users\Caio\Documents\Python\Microblog\venv\lib\site-packages\flask\app.py", line 1949, in full_dispatch_request
    rv = self.dispatch_request()
  File "e:\Users\Caio\Documents\Python\Microblog\venv\lib\site-packages\flask\app.py", line 1935, in dispatch_request
    return self.view_functions[rule.endpoint](**req.view_args)
  File "e:\Users\Caio\Documents\Python\Microblog\venv\lib\site-packages\flask_login\utils.py", line 261, in decorated_view
    return func(*args, **kwargs)
  File "e:\Users\Caio\Documents\Python\Microblog\app\routes.py", line 85, in edit_profile
    db.session.commit()
  File "e:\Users\Caio\Documents\Python\Microblog\venv\lib\site-packages\sqlalchemy\orm\scoping.py", line 162, in do
    return getattr(self.registry(), name)(*args, **kwargs)
  File "e:\Users\Caio\Documents\Python\Microblog\venv\lib\site-packages\sqlalchemy\orm\session.py", line 1027, in commit
    self.transaction.commit()
  File "e:\Users\Caio\Documents\Python\Microblog\venv\lib\site-packages\sqlalchemy\orm\session.py", line 494, in commit
    self._prepare_impl()
  File "e:\Users\Caio\Documents\Python\Microblog\venv\lib\site-packages\sqlalchemy\orm\session.py", line 473, in _prepare_impl
    self.session.flush()
  File "e:\Users\Caio\Documents\Python\Microblog\venv\lib\site-packages\sqlalchemy\orm\session.py", line 2459, in flush
    self._flush(objects)
  File "e:\Users\Caio\Documents\Python\Microblog\venv\lib\site-packages\sqlalchemy\orm\session.py", line 2597, in _flush
    transaction.rollback(_capture_exception=True)
  File "e:\Users\Caio\Documents\Python\Microblog\venv\lib\site-packages\sqlalchemy\util\langhelpers.py", line 68, in __exit__
    compat.reraise(exc_type, exc_value, exc_tb)
  File "e:\Users\Caio\Documents\Python\Microblog\venv\lib\site-packages\sqlalchemy\util\compat.py", line 153, in reraise
    raise value
  File "e:\Users\Caio\Documents\Python\Microblog\venv\lib\site-packages\sqlalchemy\orm\session.py", line 2557, in _flush
    flush_context.execute()
  File "e:\Users\Caio\Documents\Python\Microblog\venv\lib\site-packages\sqlalchemy\orm\unitofwork.py", line 422, in execute
    rec.execute(self)
  File "e:\Users\Caio\Documents\Python\Microblog\venv\lib\site-packages\sqlalchemy\orm\unitofwork.py", line 589, in execute
    uow,
  File "e:\Users\Caio\Documents\Python\Microblog\venv\lib\site-packages\sqlalchemy\orm\persistence.py", line 236, in save_obj
    update,
  File "e:\Users\Caio\Documents\Python\Microblog\venv\lib\site-packages\sqlalchemy\orm\persistence.py", line 996, in _emit_update_statements
    statement, multiparams
  File "e:\Users\Caio\Documents\Python\Microblog\venv\lib\site-packages\sqlalchemy\engine\base.py", line 988, in execute
    return meth(self, multiparams, params)
  File "e:\Users\Caio\Documents\Python\Microblog\venv\lib\site-packages\sqlalchemy\sql\elements.py", line 287, in _execute_on_connection
    return connection._execute_clauseelement(self, multiparams, params)
  File "e:\Users\Caio\Documents\Python\Microblog\venv\lib\site-packages\sqlalchemy\engine\base.py", line 1107, in _execute_clauseelement
    distilled_params,
  File "e:\Users\Caio\Documents\Python\Microblog\venv\lib\site-packages\sqlalchemy\engine\base.py", line 1248, in _execute_context
    e, statement, parameters, cursor, context
  File "e:\Users\Caio\Documents\Python\Microblog\venv\lib\site-packages\sqlalchemy\engine\base.py", line 1466, in _handle_dbapi_exception
    util.raise_from_cause(sqlalchemy_exception, exc_info)
  File "e:\Users\Caio\Documents\Python\Microblog\venv\lib\site-packages\sqlalchemy\util\compat.py", line 398, in raise_from_cause
    reraise(type(exception), exception, tb=exc_tb, cause=cause)
  File "e:\Users\Caio\Documents\Python\Microblog\venv\lib\site-packages\sqlalchemy\util\compat.py", line 152, in reraise
    raise value.with_traceback(tb)
  File "e:\Users\Caio\Documents\Python\Microblog\venv\lib\site-packages\sqlalchemy\engine\base.py", line 1244, in _execute_context
    cursor, statement, parameters, context
  File "e:\Users\Caio\Documents\Python\Microblog\venv\lib\site-packages\sqlalchemy\engine\default.py", line 552, in do_execute
    cursor.execute(statement, parameters)
sqlalchemy.exc.IntegrityError: (sqlite3.IntegrityError) UNIQUE constraint failed: user.username
[SQL: UPDATE user SET username=?, about_me=? WHERE user.id = ?]
[parameters: ('Susan', '', 1)]
(Background on this error at: http://sqlalche.me/e/gkpj)
2019-10-06 20:52:58,177 INFO: Microblog startup [ in e:\Users\Caio\Documents\Python\Microblog\app\__init__.py:43]
2019-10-13 17:41:25,296 INFO: Microblog startup [ in e:\Users\Caio\Documents\Python\Microblog\app\__init__.py:43]
2019-10-13 17:41:55,106 INFO: Microblog startup [ in e:\Users\Caio\Documents\Python\Microblog\app\__init__.py:43]
2019-10-13 17:42:06,157 INFO: Microblog startup [ in e:\Users\Caio\Documents\Python\Microblog\app\__init__.py:43]
2019-10-13 19:08:21,246 INFO: Microblog startup [ in e:\Users\Caio\Documents\Python\Microblog\app\__init__.py:43]
2019-10-21 17:47:42,981 INFO: Microblog startup [ in e:\Users\Caio\Documents\Python\Microblog\app\__init__.py:43]
2019-10-21 17:48:11,222 INFO: Microblog startup [ in e:\Users\Caio\Documents\Python\Microblog\app\__init__.py:43]
2019-10-21 17:49:18,695 INFO: Microblog startup [ in e:\Users\Caio\Documents\Python\Microblog\app\__init__.py:43]
2019-10-21 17:49:24,840 INFO: Microblog startup [ in e:\Users\Caio\Documents\Python\Microblog\app\__init__.py:43]
2019-10-21 17:51:41,524 INFO: Microblog startup [ in e:\Users\Caio\Documents\Python\Microblog\app\__init__.py:43]
2019-10-21 17:52:01,226 INFO: Microblog startup [ in e:\Users\Caio\Documents\Python\Microblog\app\__init__.py:43]
2019-10-21 17:53:47,710 INFO: Microblog startup [ in e:\Users\Caio\Documents\Python\Microblog\app\__init__.py:43]
2019-10-21 17:56:26,561 INFO: Microblog startup [ in e:\Users\Caio\Documents\Python\Microblog\app\__init__.py:43]
2019-10-21 19:29:03,413 INFO: Microblog startup [ in e:\Users\Caio\Documents\Python\Microblog\app\__init__.py:43]
2019-10-21 19:30:28,841 ERROR: Exception on /unfollow/username [GET] [ in e:\Users\Caio\Documents\Python\Microblog\venv\lib\site-packages\flask\app.py:1891]
Traceback (most recent call last):
  File "e:\Users\Caio\Documents\Python\Microblog\venv\lib\site-packages\flask\app.py", line 2446, in wsgi_app
    response = self.full_dispatch_request()
  File "e:\Users\Caio\Documents\Python\Microblog\venv\lib\site-packages\flask\app.py", line 1951, in full_dispatch_request
    rv = self.handle_user_exception(e)
  File "e:\Users\Caio\Documents\Python\Microblog\venv\lib\site-packages\flask\app.py", line 1820, in handle_user_exception
    reraise(exc_type, exc_value, tb)
  File "e:\Users\Caio\Documents\Python\Microblog\venv\lib\site-packages\flask\_compat.py", line 39, in reraise
    raise value
  File "e:\Users\Caio\Documents\Python\Microblog\venv\lib\site-packages\flask\app.py", line 1949, in full_dispatch_request
    rv = self.dispatch_request()
  File "e:\Users\Caio\Documents\Python\Microblog\venv\lib\site-packages\flask\app.py", line 1935, in dispatch_request
    return self.view_functions[rule.endpoint](**req.view_args)
  File "e:\Users\Caio\Documents\Python\Microblog\venv\lib\site-packages\flask_login\utils.py", line 261, in decorated_view
    return func(*args, **kwargs)
TypeError: unfollow() missing 1 required positional argument: 'username'
2019-10-21 19:33:45,729 INFO: Microblog startup [ in e:\Users\Caio\Documents\Python\Microblog\app\__init__.py:43]
