2019-12-01 15:10:58,513 ERROR: Exception on /index [GET] [ in e:\Users\Caio\Documents\Python\Microblog\venv\lib\site-packages\flask\app.py:1891]
Traceback (most recent call last):
  File "e:\Users\Caio\Documents\Python\Microblog\venv\lib\site-packages\flask\app.py", line 2446, in wsgi_app
    response = self.full_dispatch_request()
  File "e:\Users\Caio\Documents\Python\Microblog\venv\lib\site-packages\flask\app.py", line 1951, in full_dispatch_request
    rv = self.handle_user_exception(e)
  File "e:\Users\Caio\Documents\Python\Microblog\venv\lib\site-packages\flask\app.py", line 1820, in handle_user_exception
    reraise(exc_type, exc_value, tb)
  File "e:\Users\Caio\Documents\Python\Microblog\venv\lib\site-packages\flask\_compat.py", line 39, in reraise
    raise value
  File "e:\Users\Caio\Documents\Python\Microblog\venv\lib\site-packages\flask\app.py", line 1949, in full_dispatch_request
    rv = self.dispatch_request()
  File "e:\Users\Caio\Documents\Python\Microblog\venv\lib\site-packages\flask\app.py", line 1935, in dispatch_request
    return self.view_functions[rule.endpoint](**req.view_args)
  File "e:\Users\Caio\Documents\Python\Microblog\venv\lib\site-packages\flask_login\utils.py", line 261, in decorated_view
    return func(*args, **kwargs)
  File "e:\Users\Caio\Documents\Python\Microblog\app\routes.py", line 28, in index
    return render_template("index.html", title=_("Home Page"), form=form, posts=posts.items, next_url=next_url, prev_url=prev_url)
NameError: name '_' is not defined
2019-12-01 17:53:03,480 INFO: Microblog startup [ in e:\Users\Caio\Documents\Python\Microblog\app\__init__.py:51]
2019-12-01 17:53:45,171 INFO: Microblog startup [ in e:\Users\Caio\Documents\Python\Microblog\app\__init__.py:51]
2019-12-01 17:53:53,631 ERROR: Exception on / [GET] [ in e:\Users\Caio\Documents\Python\Microblog\venv\lib\site-packages\flask\app.py:1891]
Traceback (most recent call last):
  File "e:\Users\Caio\Documents\Python\Microblog\venv\lib\site-packages\flask\app.py", line 2446, in wsgi_app
    response = self.full_dispatch_request()
  File "e:\Users\Caio\Documents\Python\Microblog\venv\lib\site-packages\flask\app.py", line 1951, in full_dispatch_request
    rv = self.handle_user_exception(e)
  File "e:\Users\Caio\Documents\Python\Microblog\venv\lib\site-packages\flask\app.py", line 1820, in handle_user_exception
    reraise(exc_type, exc_value, tb)
  File "e:\Users\Caio\Documents\Python\Microblog\venv\lib\site-packages\flask\_compat.py", line 39, in reraise
    raise value
  File "e:\Users\Caio\Documents\Python\Microblog\venv\lib\site-packages\flask\app.py", line 1949, in full_dispatch_request
    rv = self.dispatch_request()
  File "e:\Users\Caio\Documents\Python\Microblog\venv\lib\site-packages\flask\app.py", line 1935, in dispatch_request
    return self.view_functions[rule.endpoint](**req.view_args)
  File "e:\Users\Caio\Documents\Python\Microblog\venv\lib\site-packages\flask_login\utils.py", line 261, in decorated_view
    return func(*args, **kwargs)
  File "e:\Users\Caio\Documents\Python\Microblog\app\routes.py", line 28, in index
    return render_template("index.html", title=_("Home Page"), form=form, posts=posts.items, next_url=next_url, prev_url=prev_url)
NameError: name '_' is not defined
2019-12-01 17:54:13,989 INFO: Microblog startup [ in e:\Users\Caio\Documents\Python\Microblog\app\__init__.py:51]
2019-12-01 17:55:40,319 INFO: Microblog startup [ in e:\Users\Caio\Documents\Python\Microblog\app\__init__.py:51]
2019-12-01 17:55:42,739 ERROR: Exception on / [GET] [ in e:\Users\Caio\Documents\Python\Microblog\venv\lib\site-packages\flask\app.py:1891]
Traceback (most recent call last):
  File "e:\Users\Caio\Documents\Python\Microblog\venv\lib\site-packages\flask\app.py", line 2446, in wsgi_app
    response = self.full_dispatch_request()
  File "e:\Users\Caio\Documents\Python\Microblog\venv\lib\site-packages\flask\app.py", line 1951, in full_dispatch_request
    rv = self.handle_user_exception(e)
  File "e:\Users\Caio\Documents\Python\Microblog\venv\lib\site-packages\flask\app.py", line 1820, in handle_user_exception
    reraise(exc_type, exc_value, tb)
  File "e:\Users\Caio\Documents\Python\Microblog\venv\lib\site-packages\flask\_compat.py", line 39, in reraise
    raise value
  File "e:\Users\Caio\Documents\Python\Microblog\venv\lib\site-packages\flask\app.py", line 1949, in full_dispatch_request
    rv = self.dispatch_request()
  File "e:\Users\Caio\Documents\Python\Microblog\venv\lib\site-packages\flask\app.py", line 1935, in dispatch_request
    return self.view_functions[rule.endpoint](**req.view_args)
  File "e:\Users\Caio\Documents\Python\Microblog\venv\lib\site-packages\flask_login\utils.py", line 261, in decorated_view
    return func(*args, **kwargs)
  File "e:\Users\Caio\Documents\Python\Microblog\app\routes.py", line 28, in index
    return render_template("index.html", title=_('Home Page'), form=form, posts=posts.items, next_url=next_url, prev_url=prev_url)
NameError: name '_' is not defined
2019-12-01 17:57:21,497 INFO: Microblog startup [ in e:\Users\Caio\Documents\Python\Microblog\app\__init__.py:51]
2019-12-01 17:57:24,275 ERROR: Exception on / [GET] [ in e:\Users\Caio\Documents\Python\Microblog\venv\lib\site-packages\flask\app.py:1891]
Traceback (most recent call last):
  File "e:\Users\Caio\Documents\Python\Microblog\venv\lib\site-packages\flask\app.py", line 2446, in wsgi_app
    response = self.full_dispatch_request()
  File "e:\Users\Caio\Documents\Python\Microblog\venv\lib\site-packages\flask\app.py", line 1951, in full_dispatch_request
    rv = self.handle_user_exception(e)
  File "e:\Users\Caio\Documents\Python\Microblog\venv\lib\site-packages\flask\app.py", line 1820, in handle_user_exception
    reraise(exc_type, exc_value, tb)
  File "e:\Users\Caio\Documents\Python\Microblog\venv\lib\site-packages\flask\_compat.py", line 39, in reraise
    raise value
  File "e:\Users\Caio\Documents\Python\Microblog\venv\lib\site-packages\flask\app.py", line 1949, in full_dispatch_request
    rv = self.dispatch_request()
  File "e:\Users\Caio\Documents\Python\Microblog\venv\lib\site-packages\flask\app.py", line 1935, in dispatch_request
    return self.view_functions[rule.endpoint](**req.view_args)
  File "e:\Users\Caio\Documents\Python\Microblog\venv\lib\site-packages\flask_login\utils.py", line 261, in decorated_view
    return func(*args, **kwargs)
  File "e:\Users\Caio\Documents\Python\Microblog\app\routes.py", line 28, in index
    return render_template("index.html", title=_("Home Page"), form=form, posts=posts.items, next_url=next_url, prev_url=prev_url)
NameError: name '_' is not defined
2019-12-01 17:57:32,317 ERROR: Exception on /index [GET] [ in e:\Users\Caio\Documents\Python\Microblog\venv\lib\site-packages\flask\app.py:1891]
Traceback (most recent call last):
  File "e:\Users\Caio\Documents\Python\Microblog\venv\lib\site-packages\flask\app.py", line 2446, in wsgi_app
    response = self.full_dispatch_request()
  File "e:\Users\Caio\Documents\Python\Microblog\venv\lib\site-packages\flask\app.py", line 1951, in full_dispatch_request
    rv = self.handle_user_exception(e)
  File "e:\Users\Caio\Documents\Python\Microblog\venv\lib\site-packages\flask\app.py", line 1820, in handle_user_exception
    reraise(exc_type, exc_value, tb)
  File "e:\Users\Caio\Documents\Python\Microblog\venv\lib\site-packages\flask\_compat.py", line 39, in reraise
    raise value
  File "e:\Users\Caio\Documents\Python\Microblog\venv\lib\site-packages\flask\app.py", line 1949, in full_dispatch_request
    rv = self.dispatch_request()
  File "e:\Users\Caio\Documents\Python\Microblog\venv\lib\site-packages\flask\app.py", line 1935, in dispatch_request
    return self.view_functions[rule.endpoint](**req.view_args)
  File "e:\Users\Caio\Documents\Python\Microblog\venv\lib\site-packages\flask_login\utils.py", line 261, in decorated_view
    return func(*args, **kwargs)
  File "e:\Users\Caio\Documents\Python\Microblog\app\routes.py", line 28, in index
    return render_template("index.html", title=_("Home Page"), form=form, posts=posts.items, next_url=next_url, prev_url=prev_url)
NameError: name '_' is not defined
2019-12-01 17:57:33,337 ERROR: Exception on /explore [GET] [ in e:\Users\Caio\Documents\Python\Microblog\venv\lib\site-packages\flask\app.py:1891]
Traceback (most recent call last):
  File "e:\Users\Caio\Documents\Python\Microblog\venv\lib\site-packages\flask\app.py", line 2446, in wsgi_app
    response = self.full_dispatch_request()
  File "e:\Users\Caio\Documents\Python\Microblog\venv\lib\site-packages\flask\app.py", line 1951, in full_dispatch_request
    rv = self.handle_user_exception(e)
  File "e:\Users\Caio\Documents\Python\Microblog\venv\lib\site-packages\flask\app.py", line 1820, in handle_user_exception
    reraise(exc_type, exc_value, tb)
  File "e:\Users\Caio\Documents\Python\Microblog\venv\lib\site-packages\flask\_compat.py", line 39, in reraise
    raise value
  File "e:\Users\Caio\Documents\Python\Microblog\venv\lib\site-packages\flask\app.py", line 1949, in full_dispatch_request
    rv = self.dispatch_request()
  File "e:\Users\Caio\Documents\Python\Microblog\venv\lib\site-packages\flask\app.py", line 1935, in dispatch_request
    return self.view_functions[rule.endpoint](**req.view_args)
  File "e:\Users\Caio\Documents\Python\Microblog\venv\lib\site-packages\flask_login\utils.py", line 261, in decorated_view
    return func(*args, **kwargs)
  File "e:\Users\Caio\Documents\Python\Microblog\app\routes.py", line 40, in explore
    return render_template("explore.html", title=_("Explore"), posts=posts.items, next_url=next_url, prev_url=prev_url)
NameError: name '_' is not defined
