2019-10-21 19:33:49,709 ERROR: Exception on /unfollow/username [GET] [ in e:\Users\Caio\Documents\Python\Microblog\venv\lib\site-packages\flask\app.py:1891]
Traceback (most recent call last):
  File "e:\Users\Caio\Documents\Python\Microblog\venv\lib\site-packages\flask\app.py", line 2446, in wsgi_app
    response = self.full_dispatch_request()
  File "e:\Users\Caio\Documents\Python\Microblog\venv\lib\site-packages\flask\app.py", line 1951, in full_dispatch_request
    rv = self.handle_user_exception(e)
  File "e:\Users\Caio\Documents\Python\Microblog\venv\lib\site-packages\flask\app.py", line 1820, in handle_user_exception
    reraise(exc_type, exc_value, tb)
  File "e:\Users\Caio\Documents\Python\Microblog\venv\lib\site-packages\flask\_compat.py", line 39, in reraise
    raise value
  File "e:\Users\Caio\Documents\Python\Microblog\venv\lib\site-packages\flask\app.py", line 1949, in full_dispatch_request
    rv = self.dispatch_request()
  File "e:\Users\Caio\Documents\Python\Microblog\venv\lib\site-packages\flask\app.py", line 1935, in dispatch_request
    return self.view_functions[rule.endpoint](**req.view_args)
  File "e:\Users\Caio\Documents\Python\Microblog\venv\lib\site-packages\flask_login\utils.py", line 261, in decorated_view
    return func(*args, **kwargs)
TypeError: unfollow() missing 1 required positional argument: 'username'
2019-10-21 19:34:00,258 ERROR: Exception on /unfollow/username [GET] [ in e:\Users\Caio\Documents\Python\Microblog\venv\lib\site-packages\flask\app.py:1891]
Traceback (most recent call last):
  File "e:\Users\Caio\Documents\Python\Microblog\venv\lib\site-packages\flask\app.py", line 2446, in wsgi_app
    response = self.full_dispatch_request()
  File "e:\Users\Caio\Documents\Python\Microblog\venv\lib\site-packages\flask\app.py", line 1951, in full_dispatch_request
    rv = self.handle_user_exception(e)
  File "e:\Users\Caio\Documents\Python\Microblog\venv\lib\site-packages\flask\app.py", line 1820, in handle_user_exception
    reraise(exc_type, exc_value, tb)
  File "e:\Users\Caio\Documents\Python\Microblog\venv\lib\site-packages\flask\_compat.py", line 39, in reraise
    raise value
  File "e:\Users\Caio\Documents\Python\Microblog\venv\lib\site-packages\flask\app.py", line 1949, in full_dispatch_request
    rv = self.dispatch_request()
  File "e:\Users\Caio\Documents\Python\Microblog\venv\lib\site-packages\flask\app.py", line 1935, in dispatch_request
    return self.view_functions[rule.endpoint](**req.view_args)
  File "e:\Users\Caio\Documents\Python\Microblog\venv\lib\site-packages\flask_login\utils.py", line 261, in decorated_view
    return func(*args, **kwargs)
TypeError: unfollow() missing 1 required positional argument: 'username'
2019-10-25 14:31:46,785 INFO: Microblog startup [ in e:\Users\Caio\Documents\Python\Microblog\app\__init__.py:43]
2019-10-25 14:31:56,313 ERROR: Exception on /unfollow/username [GET] [ in e:\Users\Caio\Documents\Python\Microblog\venv\lib\site-packages\flask\app.py:1891]
Traceback (most recent call last):
  File "e:\Users\Caio\Documents\Python\Microblog\venv\lib\site-packages\flask\app.py", line 2446, in wsgi_app
    response = self.full_dispatch_request()
  File "e:\Users\Caio\Documents\Python\Microblog\venv\lib\site-packages\flask\app.py", line 1951, in full_dispatch_request
    rv = self.handle_user_exception(e)
  File "e:\Users\Caio\Documents\Python\Microblog\venv\lib\site-packages\flask\app.py", line 1820, in handle_user_exception
    reraise(exc_type, exc_value, tb)
  File "e:\Users\Caio\Documents\Python\Microblog\venv\lib\site-packages\flask\_compat.py", line 39, in reraise
    raise value
  File "e:\Users\Caio\Documents\Python\Microblog\venv\lib\site-packages\flask\app.py", line 1949, in full_dispatch_request
    rv = self.dispatch_request()
  File "e:\Users\Caio\Documents\Python\Microblog\venv\lib\site-packages\flask\app.py", line 1935, in dispatch_request
    return self.view_functions[rule.endpoint](**req.view_args)
  File "e:\Users\Caio\Documents\Python\Microblog\venv\lib\site-packages\flask_login\utils.py", line 261, in decorated_view
    return func(*args, **kwargs)
TypeError: unfollow() missing 1 required positional argument: 'username'
2019-10-25 14:32:14,782 ERROR: Exception on /unfollow/username [GET] [ in e:\Users\Caio\Documents\Python\Microblog\venv\lib\site-packages\flask\app.py:1891]
Traceback (most recent call last):
  File "e:\Users\Caio\Documents\Python\Microblog\venv\lib\site-packages\flask\app.py", line 2446, in wsgi_app
    response = self.full_dispatch_request()
  File "e:\Users\Caio\Documents\Python\Microblog\venv\lib\site-packages\flask\app.py", line 1951, in full_dispatch_request
    rv = self.handle_user_exception(e)
  File "e:\Users\Caio\Documents\Python\Microblog\venv\lib\site-packages\flask\app.py", line 1820, in handle_user_exception
    reraise(exc_type, exc_value, tb)
  File "e:\Users\Caio\Documents\Python\Microblog\venv\lib\site-packages\flask\_compat.py", line 39, in reraise
    raise value
  File "e:\Users\Caio\Documents\Python\Microblog\venv\lib\site-packages\flask\app.py", line 1949, in full_dispatch_request
    rv = self.dispatch_request()
  File "e:\Users\Caio\Documents\Python\Microblog\venv\lib\site-packages\flask\app.py", line 1935, in dispatch_request
    return self.view_functions[rule.endpoint](**req.view_args)
  File "e:\Users\Caio\Documents\Python\Microblog\venv\lib\site-packages\flask_login\utils.py", line 261, in decorated_view
    return func(*args, **kwargs)
TypeError: unfollow() missing 1 required positional argument: 'username'
2019-10-25 14:41:17,368 INFO: Microblog startup [ in e:\Users\Caio\Documents\Python\Microblog\app\__init__.py:43]
2019-10-25 14:41:33,588 ERROR: Exception on /unfollow/username [GET] [ in e:\Users\Caio\Documents\Python\Microblog\venv\lib\site-packages\flask\app.py:1891]
Traceback (most recent call last):
  File "e:\Users\Caio\Documents\Python\Microblog\venv\lib\site-packages\flask\app.py", line 2446, in wsgi_app
    response = self.full_dispatch_request()
  File "e:\Users\Caio\Documents\Python\Microblog\venv\lib\site-packages\flask\app.py", line 1951, in full_dispatch_request
    rv = self.handle_user_exception(e)
  File "e:\Users\Caio\Documents\Python\Microblog\venv\lib\site-packages\flask\app.py", line 1820, in handle_user_exception
    reraise(exc_type, exc_value, tb)
  File "e:\Users\Caio\Documents\Python\Microblog\venv\lib\site-packages\flask\_compat.py", line 39, in reraise
    raise value
  File "e:\Users\Caio\Documents\Python\Microblog\venv\lib\site-packages\flask\app.py", line 1949, in full_dispatch_request
    rv = self.dispatch_request()
  File "e:\Users\Caio\Documents\Python\Microblog\venv\lib\site-packages\flask\app.py", line 1935, in dispatch_request
    return self.view_functions[rule.endpoint](**req.view_args)
  File "e:\Users\Caio\Documents\Python\Microblog\venv\lib\site-packages\flask_login\utils.py", line 261, in decorated_view
    return func(*args, **kwargs)
TypeError: unfollow() missing 1 required positional argument: 'username'
2019-10-25 14:42:30,615 INFO: Microblog startup [ in e:\Users\Caio\Documents\Python\Microblog\app\__init__.py:43]
2019-10-25 14:45:13,412 INFO: Microblog startup [ in e:\Users\Caio\Documents\Python\Microblog\app\__init__.py:43]
2019-10-25 14:45:50,404 INFO: Microblog startup [ in e:\Users\Caio\Documents\Python\Microblog\app\__init__.py:43]
2019-10-25 15:31:30,162 INFO: Microblog startup [ in e:\Users\Caio\Documents\Python\Microblog\app\__init__.py:43]
2019-10-25 15:32:40,263 INFO: Microblog startup [ in e:\Users\Caio\Documents\Python\Microblog\app\__init__.py:43]
2019-10-25 15:52:11,292 INFO: Microblog startup [ in e:\Users\Caio\Documents\Python\Microblog\app\__init__.py:43]
2019-10-25 15:52:45,578 INFO: Microblog startup [ in e:\Users\Caio\Documents\Python\Microblog\app\__init__.py:43]
2019-10-25 17:05:19,721 INFO: Microblog startup [ in e:\Users\Caio\Documents\Python\Microblog\app\__init__.py:43]
2019-10-28 12:03:46,018 INFO: Microblog startup [ in e:\Users\Caio\Documents\Python\Microblog\app\__init__.py:43]
2019-10-28 12:12:06,037 INFO: Microblog startup [ in e:\Users\Caio\Documents\Python\Microblog\app\__init__.py:43]
2019-10-28 12:12:09,429 ERROR: Exception on /user/John [GET] [ in e:\Users\Caio\Documents\Python\Microblog\venv\lib\site-packages\flask\app.py:1891]
Traceback (most recent call last):
  File "e:\Users\Caio\Documents\Python\Microblog\venv\lib\site-packages\flask\app.py", line 2446, in wsgi_app
    response = self.full_dispatch_request()
  File "e:\Users\Caio\Documents\Python\Microblog\venv\lib\site-packages\flask\app.py", line 1951, in full_dispatch_request
    rv = self.handle_user_exception(e)
  File "e:\Users\Caio\Documents\Python\Microblog\venv\lib\site-packages\flask\app.py", line 1820, in handle_user_exception
    reraise(exc_type, exc_value, tb)
  File "e:\Users\Caio\Documents\Python\Microblog\venv\lib\site-packages\flask\_compat.py", line 39, in reraise
    raise value
  File "e:\Users\Caio\Documents\Python\Microblog\venv\lib\site-packages\flask\app.py", line 1949, in full_dispatch_request
    rv = self.dispatch_request()
  File "e:\Users\Caio\Documents\Python\Microblog\venv\lib\site-packages\flask\app.py", line 1935, in dispatch_request
    return self.view_functions[rule.endpoint](**req.view_args)
  File "e:\Users\Caio\Documents\Python\Microblog\venv\lib\site-packages\flask_login\utils.py", line 261, in decorated_view
    return func(*args, **kwargs)
  File "e:\Users\Caio\Documents\Python\Microblog\app\routes.py", line 83, in user
    page, app.config["POSTS_PER_PAGE"], False)
NameError: name 'app' is not defined
