2019-10-28 12:12:13,400 ERROR: Exception on /user/John [GET] [ in e:\Users\Caio\Documents\Python\Microblog\venv\lib\site-packages\flask\app.py:1891]
Traceback (most recent call last):
  File "e:\Users\Caio\Documents\Python\Microblog\venv\lib\site-packages\flask\app.py", line 2446, in wsgi_app
    response = self.full_dispatch_request()
  File "e:\Users\Caio\Documents\Python\Microblog\venv\lib\site-packages\flask\app.py", line 1951, in full_dispatch_request
    rv = self.handle_user_exception(e)
  File "e:\Users\Caio\Documents\Python\Microblog\venv\lib\site-packages\flask\app.py", line 1820, in handle_user_exception
    reraise(exc_type, exc_value, tb)
  File "e:\Users\Caio\Documents\Python\Microblog\venv\lib\site-packages\flask\_compat.py", line 39, in reraise
    raise value
  File "e:\Users\Caio\Documents\Python\Microblog\venv\lib\site-packages\flask\app.py", line 1949, in full_dispatch_request
    rv = self.dispatch_request()
  File "e:\Users\Caio\Documents\Python\Microblog\venv\lib\site-packages\flask\app.py", line 1935, in dispatch_request
    return self.view_functions[rule.endpoint](**req.view_args)
  File "e:\Users\Caio\Documents\Python\Microblog\venv\lib\site-packages\flask_login\utils.py", line 261, in decorated_view
    return func(*args, **kwargs)
  File "e:\Users\Caio\Documents\Python\Microblog\app\routes.py", line 83, in user
    page, app.config["POSTS_PER_PAGE"], False)
NameError: name 'app' is not defined
2019-10-28 12:13:01,873 INFO: Microblog startup [ in e:\Users\Caio\Documents\Python\Microblog\app\__init__.py:43]
2019-10-28 12:41:10,078 INFO: Microblog startup [ in e:\Users\Caio\Documents\Python\Microblog\app\__init__.py:43]
2019-10-28 12:41:29,158 INFO: Microblog startup [ in e:\Users\Caio\Documents\Python\Microblog\app\__init__.py:43]
2019-11-01 22:32:05,177 INFO: Microblog startup [ in e:\Users\Caio\Documents\Python\Microblog\app\__init__.py:43]
2019-11-01 22:47:08,794 INFO: Microblog startup [ in E:\Users\Caio\Documents\Python\Microblog\app\__init__.py:43]
2019-11-03 21:56:21,337 INFO: Microblog startup [ in e:\Users\Caio\Documents\Python\Microblog\app\__init__.py:45]
2019-11-03 22:15:32,396 INFO: Microblog startup [ in e:\Users\Caio\Documents\Python\Microblog\app\__init__.py:45]
2019-11-03 22:29:02,260 INFO: Microblog startup [ in e:\Users\Caio\Documents\Python\Microblog\app\__init__.py:45]
2019-11-03 22:31:26,857 INFO: Microblog startup [ in e:\Users\Caio\Documents\Python\Microblog\app\__init__.py:45]
2019-11-03 22:33:41,906 INFO: Microblog startup [ in e:\Users\Caio\Documents\Python\Microblog\app\__init__.py:45]
2019-11-03 22:33:53,215 ERROR: Exception on /reset_password_request [GET] [ in e:\Users\Caio\Documents\Python\Microblog\venv\lib\site-packages\flask\app.py:1891]
Traceback (most recent call last):
  File "e:\Users\Caio\Documents\Python\Microblog\venv\lib\site-packages\flask\app.py", line 2446, in wsgi_app
    response = self.full_dispatch_request()
  File "e:\Users\Caio\Documents\Python\Microblog\venv\lib\site-packages\flask\app.py", line 1951, in full_dispatch_request
    rv = self.handle_user_exception(e)
  File "e:\Users\Caio\Documents\Python\Microblog\venv\lib\site-packages\flask\app.py", line 1820, in handle_user_exception
    reraise(exc_type, exc_value, tb)
  File "e:\Users\Caio\Documents\Python\Microblog\venv\lib\site-packages\flask\_compat.py", line 39, in reraise
    raise value
  File "e:\Users\Caio\Documents\Python\Microblog\venv\lib\site-packages\flask\app.py", line 1949, in full_dispatch_request
    rv = self.dispatch_request()
  File "e:\Users\Caio\Documents\Python\Microblog\venv\lib\site-packages\flask\app.py", line 1935, in dispatch_request
    return self.view_functions[rule.endpoint](**req.view_args)
  File "e:\Users\Caio\Documents\Python\Microblog\app\routes.py", line 153, in reset_password_request
    return render_template("reset_password_request.html", title="Reset Password", form=form)
  File "e:\Users\Caio\Documents\Python\Microblog\venv\lib\site-packages\flask\templating.py", line 138, in render_template
    ctx.app.jinja_env.get_or_select_template(template_name_or_list),
  File "e:\Users\Caio\Documents\Python\Microblog\venv\lib\site-packages\jinja2\environment.py", line 869, in get_or_select_template
    return self.get_template(template_name_or_list, parent, globals)
  File "e:\Users\Caio\Documents\Python\Microblog\venv\lib\site-packages\jinja2\environment.py", line 830, in get_template
    return self._load_template(name, self.make_globals(globals))
  File "e:\Users\Caio\Documents\Python\Microblog\venv\lib\site-packages\jinja2\environment.py", line 804, in _load_template
    template = self.loader.load(self, name, globals)
  File "e:\Users\Caio\Documents\Python\Microblog\venv\lib\site-packages\jinja2\loaders.py", line 113, in load
    source, filename, uptodate = self.get_source(environment, name)
  File "e:\Users\Caio\Documents\Python\Microblog\venv\lib\site-packages\flask\templating.py", line 60, in get_source
    return self._get_source_fast(environment, template)
  File "e:\Users\Caio\Documents\Python\Microblog\venv\lib\site-packages\flask\templating.py", line 89, in _get_source_fast
    raise TemplateNotFound(template)
jinja2.exceptions.TemplateNotFound: reset_password_request.html
2019-11-03 22:34:19,555 INFO: Microblog startup [ in e:\Users\Caio\Documents\Python\Microblog\app\__init__.py:45]
2019-11-03 22:36:07,340 INFO: Microblog startup [ in e:\Users\Caio\Documents\Python\Microblog\app\__init__.py:45]
2019-11-03 22:38:17,488 INFO: Microblog startup [ in e:\Users\Caio\Documents\Python\Microblog\app\__init__.py:45]
2019-11-03 22:39:06,718 INFO: Microblog startup [ in e:\Users\Caio\Documents\Python\Microblog\app\__init__.py:45]
2019-11-03 22:40:27,442 INFO: Microblog startup [ in e:\Users\Caio\Documents\Python\Microblog\app\__init__.py:45]
2019-11-10 19:58:55,071 INFO: Microblog startup [ in e:\Users\Caio\Documents\Python\Microblog\app\__init__.py:45]
2019-11-10 20:00:41,506 INFO: Microblog startup [ in e:\Users\Caio\Documents\Python\Microblog\app\__init__.py:45]
2019-11-10 20:02:00,930 INFO: Microblog startup [ in e:\Users\Caio\Documents\Python\Microblog\app\__init__.py:45]
2019-11-10 20:09:06,955 INFO: Microblog startup [ in e:\Users\Caio\Documents\Python\Microblog\app\__init__.py:45]
2019-11-17 17:59:09,199 INFO: Microblog startup [ in e:\Users\Caio\Documents\Python\Microblog\app\__init__.py:45]
2019-11-17 20:13:34,047 INFO: Microblog startup [ in e:\Users\Caio\Documents\Python\Microblog\app\__init__.py:47]
2019-11-17 20:15:21,816 INFO: Microblog startup [ in e:\Users\Caio\Documents\Python\Microblog\app\__init__.py:47]
2019-11-24 16:34:27,401 INFO: Microblog startup [ in e:\Users\Caio\Documents\Python\Microblog\app\__init__.py:47]
2019-11-24 17:00:52,483 INFO: Microblog startup [ in e:\Users\Caio\Documents\Python\Microblog\app\__init__.py:49]
2019-12-01 14:58:49,789 INFO: Microblog startup [ in e:\Users\Caio\Documents\Python\Microblog\app\__init__.py:51]
2019-12-01 14:58:53,151 ERROR: Exception on /explore [GET] [ in e:\Users\Caio\Documents\Python\Microblog\venv\lib\site-packages\flask\app.py:1891]
Traceback (most recent call last):
  File "e:\Users\Caio\Documents\Python\Microblog\venv\lib\site-packages\flask\app.py", line 2446, in wsgi_app
    response = self.full_dispatch_request()
  File "e:\Users\Caio\Documents\Python\Microblog\venv\lib\site-packages\flask\app.py", line 1951, in full_dispatch_request
    rv = self.handle_user_exception(e)
  File "e:\Users\Caio\Documents\Python\Microblog\venv\lib\site-packages\flask\app.py", line 1820, in handle_user_exception
    reraise(exc_type, exc_value, tb)
  File "e:\Users\Caio\Documents\Python\Microblog\venv\lib\site-packages\flask\_compat.py", line 39, in reraise
    raise value
  File "e:\Users\Caio\Documents\Python\Microblog\venv\lib\site-packages\flask\app.py", line 1949, in full_dispatch_request
    rv = self.dispatch_request()
  File "e:\Users\Caio\Documents\Python\Microblog\venv\lib\site-packages\flask\app.py", line 1935, in dispatch_request
    return self.view_functions[rule.endpoint](**req.view_args)
  File "e:\Users\Caio\Documents\Python\Microblog\venv\lib\site-packages\flask_login\utils.py", line 261, in decorated_view
    return func(*args, **kwargs)
  File "e:\Users\Caio\Documents\Python\Microblog\app\routes.py", line 40, in explore
    return render_template("explore.html", title=_("Explore"), posts=posts.items, next_url=next_url, prev_url=prev_url)
NameError: name '_' is not defined
2019-12-01 15:10:49,822 INFO: Microblog startup [ in e:\Users\Caio\Documents\Python\Microblog\app\__init__.py:51]
2019-12-01 15:10:56,062 ERROR: Exception on /explore [GET] [ in e:\Users\Caio\Documents\Python\Microblog\venv\lib\site-packages\flask\app.py:1891]
Traceback (most recent call last):
  File "e:\Users\Caio\Documents\Python\Microblog\venv\lib\site-packages\flask\app.py", line 2446, in wsgi_app
    response = self.full_dispatch_request()
  File "e:\Users\Caio\Documents\Python\Microblog\venv\lib\site-packages\flask\app.py", line 1951, in full_dispatch_request
    rv = self.handle_user_exception(e)
  File "e:\Users\Caio\Documents\Python\Microblog\venv\lib\site-packages\flask\app.py", line 1820, in handle_user_exception
    reraise(exc_type, exc_value, tb)
  File "e:\Users\Caio\Documents\Python\Microblog\venv\lib\site-packages\flask\_compat.py", line 39, in reraise
    raise value
  File "e:\Users\Caio\Documents\Python\Microblog\venv\lib\site-packages\flask\app.py", line 1949, in full_dispatch_request
    rv = self.dispatch_request()
  File "e:\Users\Caio\Documents\Python\Microblog\venv\lib\site-packages\flask\app.py", line 1935, in dispatch_request
    return self.view_functions[rule.endpoint](**req.view_args)
  File "e:\Users\Caio\Documents\Python\Microblog\venv\lib\site-packages\flask_login\utils.py", line 261, in decorated_view
    return func(*args, **kwargs)
  File "e:\Users\Caio\Documents\Python\Microblog\app\routes.py", line 40, in explore
    return render_template("explore.html", title=_("Explore"), posts=posts.items, next_url=next_url, prev_url=prev_url)
NameError: name '_' is not defined
