2019-12-01 18:07:11,794 ERROR: Exception on /login [GET] [ in e:\Users\Caio\Documents\Python\Microblog\venv\lib\site-packages\flask\app.py:1891]
Traceback (most recent call last):
  File "e:\Users\Caio\Documents\Python\Microblog\venv\lib\site-packages\flask\app.py", line 2446, in wsgi_app
    response = self.full_dispatch_request()
  File "e:\Users\Caio\Documents\Python\Microblog\venv\lib\site-packages\flask\app.py", line 1951, in full_dispatch_request
    rv = self.handle_user_exception(e)
  File "e:\Users\Caio\Documents\Python\Microblog\venv\lib\site-packages\flask\app.py", line 1820, in handle_user_exception
    reraise(exc_type, exc_value, tb)
  File "e:\Users\Caio\Documents\Python\Microblog\venv\lib\site-packages\flask\_compat.py", line 39, in reraise
    raise value
  File "e:\Users\Caio\Documents\Python\Microblog\venv\lib\site-packages\flask\app.py", line 1949, in full_dispatch_request
    rv = self.dispatch_request()
  File "e:\Users\Caio\Documents\Python\Microblog\venv\lib\site-packages\flask\app.py", line 1935, in dispatch_request
    return self.view_functions[rule.endpoint](**req.view_args)
  File "e:\Users\Caio\Documents\Python\Microblog\app\routes.py", line 57, in login
    return render_template('login.html', title=_('Sign In'), form=form)
NameError: name '_' is not defined
2019-12-01 18:08:04,346 INFO: Microblog startup [ in e:\Users\Caio\Documents\Python\Microblog\app\__init__.py:51]
2019-12-01 18:08:10,494 ERROR: Exception on /login [GET] [ in e:\Users\Caio\Documents\Python\Microblog\venv\lib\site-packages\flask\app.py:1891]
Traceback (most recent call last):
  File "e:\Users\Caio\Documents\Python\Microblog\venv\lib\site-packages\flask\app.py", line 2446, in wsgi_app
    response = self.full_dispatch_request()
  File "e:\Users\Caio\Documents\Python\Microblog\venv\lib\site-packages\flask\app.py", line 1951, in full_dispatch_request
    rv = self.handle_user_exception(e)
  File "e:\Users\Caio\Documents\Python\Microblog\venv\lib\site-packages\flask\app.py", line 1820, in handle_user_exception
    reraise(exc_type, exc_value, tb)
  File "e:\Users\Caio\Documents\Python\Microblog\venv\lib\site-packages\flask\_compat.py", line 39, in reraise
    raise value
  File "e:\Users\Caio\Documents\Python\Microblog\venv\lib\site-packages\flask\app.py", line 1949, in full_dispatch_request
    rv = self.dispatch_request()
  File "e:\Users\Caio\Documents\Python\Microblog\venv\lib\site-packages\flask\app.py", line 1935, in dispatch_request
    return self.view_functions[rule.endpoint](**req.view_args)
  File "e:\Users\Caio\Documents\Python\Microblog\app\routes.py", line 57, in login
    return render_template('login.html', title=_('Sign In'), form=form)
NameError: name '_' is not defined
2019-12-01 18:08:13,031 ERROR: Exception on /login [GET] [ in e:\Users\Caio\Documents\Python\Microblog\venv\lib\site-packages\flask\app.py:1891]
Traceback (most recent call last):
  File "e:\Users\Caio\Documents\Python\Microblog\venv\lib\site-packages\flask\app.py", line 2446, in wsgi_app
    response = self.full_dispatch_request()
  File "e:\Users\Caio\Documents\Python\Microblog\venv\lib\site-packages\flask\app.py", line 1951, in full_dispatch_request
    rv = self.handle_user_exception(e)
  File "e:\Users\Caio\Documents\Python\Microblog\venv\lib\site-packages\flask\app.py", line 1820, in handle_user_exception
    reraise(exc_type, exc_value, tb)
  File "e:\Users\Caio\Documents\Python\Microblog\venv\lib\site-packages\flask\_compat.py", line 39, in reraise
    raise value
  File "e:\Users\Caio\Documents\Python\Microblog\venv\lib\site-packages\flask\app.py", line 1949, in full_dispatch_request
    rv = self.dispatch_request()
  File "e:\Users\Caio\Documents\Python\Microblog\venv\lib\site-packages\flask\app.py", line 1935, in dispatch_request
    return self.view_functions[rule.endpoint](**req.view_args)
  File "e:\Users\Caio\Documents\Python\Microblog\app\routes.py", line 57, in login
    return render_template('login.html', title=_('Sign In'), form=form)
NameError: name '_' is not defined
2019-12-01 18:08:14,005 ERROR: Exception on /login [GET] [ in e:\Users\Caio\Documents\Python\Microblog\venv\lib\site-packages\flask\app.py:1891]
Traceback (most recent call last):
  File "e:\Users\Caio\Documents\Python\Microblog\venv\lib\site-packages\flask\app.py", line 2446, in wsgi_app
    response = self.full_dispatch_request()
  File "e:\Users\Caio\Documents\Python\Microblog\venv\lib\site-packages\flask\app.py", line 1951, in full_dispatch_request
    rv = self.handle_user_exception(e)
  File "e:\Users\Caio\Documents\Python\Microblog\venv\lib\site-packages\flask\app.py", line 1820, in handle_user_exception
    reraise(exc_type, exc_value, tb)
  File "e:\Users\Caio\Documents\Python\Microblog\venv\lib\site-packages\flask\_compat.py", line 39, in reraise
    raise value
  File "e:\Users\Caio\Documents\Python\Microblog\venv\lib\site-packages\flask\app.py", line 1949, in full_dispatch_request
    rv = self.dispatch_request()
  File "e:\Users\Caio\Documents\Python\Microblog\venv\lib\site-packages\flask\app.py", line 1935, in dispatch_request
    return self.view_functions[rule.endpoint](**req.view_args)
  File "e:\Users\Caio\Documents\Python\Microblog\app\routes.py", line 57, in login
    return render_template('login.html', title=_('Sign In'), form=form)
NameError: name '_' is not defined
2019-12-01 18:08:15,917 ERROR: Exception on /login [GET] [ in e:\Users\Caio\Documents\Python\Microblog\venv\lib\site-packages\flask\app.py:1891]
Traceback (most recent call last):
  File "e:\Users\Caio\Documents\Python\Microblog\venv\lib\site-packages\flask\app.py", line 2446, in wsgi_app
    response = self.full_dispatch_request()
  File "e:\Users\Caio\Documents\Python\Microblog\venv\lib\site-packages\flask\app.py", line 1951, in full_dispatch_request
    rv = self.handle_user_exception(e)
  File "e:\Users\Caio\Documents\Python\Microblog\venv\lib\site-packages\flask\app.py", line 1820, in handle_user_exception
    reraise(exc_type, exc_value, tb)
  File "e:\Users\Caio\Documents\Python\Microblog\venv\lib\site-packages\flask\_compat.py", line 39, in reraise
    raise value
  File "e:\Users\Caio\Documents\Python\Microblog\venv\lib\site-packages\flask\app.py", line 1949, in full_dispatch_request
    rv = self.dispatch_request()
  File "e:\Users\Caio\Documents\Python\Microblog\venv\lib\site-packages\flask\app.py", line 1935, in dispatch_request
    return self.view_functions[rule.endpoint](**req.view_args)
  File "e:\Users\Caio\Documents\Python\Microblog\app\routes.py", line 57, in login
    return render_template('login.html', title=_('Sign In'), form=form)
NameError: name '_' is not defined
2019-12-01 18:08:19,238 ERROR: Exception on /login [GET] [ in e:\Users\Caio\Documents\Python\Microblog\venv\lib\site-packages\flask\app.py:1891]
Traceback (most recent call last):
  File "e:\Users\Caio\Documents\Python\Microblog\venv\lib\site-packages\flask\app.py", line 2446, in wsgi_app
    response = self.full_dispatch_request()
  File "e:\Users\Caio\Documents\Python\Microblog\venv\lib\site-packages\flask\app.py", line 1951, in full_dispatch_request
    rv = self.handle_user_exception(e)
  File "e:\Users\Caio\Documents\Python\Microblog\venv\lib\site-packages\flask\app.py", line 1820, in handle_user_exception
    reraise(exc_type, exc_value, tb)
  File "e:\Users\Caio\Documents\Python\Microblog\venv\lib\site-packages\flask\_compat.py", line 39, in reraise
    raise value
  File "e:\Users\Caio\Documents\Python\Microblog\venv\lib\site-packages\flask\app.py", line 1949, in full_dispatch_request
    rv = self.dispatch_request()
  File "e:\Users\Caio\Documents\Python\Microblog\venv\lib\site-packages\flask\app.py", line 1935, in dispatch_request
    return self.view_functions[rule.endpoint](**req.view_args)
  File "e:\Users\Caio\Documents\Python\Microblog\app\routes.py", line 57, in login
    return render_template('login.html', title=_('Sign In'), form=form)
NameError: name '_' is not defined
2019-12-01 18:09:18,258 INFO: Microblog startup [ in e:\Users\Caio\Documents\Python\Microblog\app\__init__.py:51]
2019-12-01 18:18:12,672 INFO: Microblog startup [ in e:\Users\Caio\Documents\Python\Microblog\app\__init__.py:51]
2019-12-27 13:43:22,554 INFO: Microblog startup [ in e:\Users\Caio\Documents\Python\Microblog\app\__init__.py:51]
